Workbook

Sheet Hướng dẫn
B1: FoodRescue - Checklist công việc nhóm
B2: Nguồn: docs/FoodRescue_KeHoachPhanCong.pdf (thẻ việc mục 4, cổng kiểm tra mục 3). Mỗi việc được tách thành từng bước để tick.
B4: Cách dùng
B5: 1. Mỗi người mở sheet của mình (TV1 ... TV4), ghi tên vào ô màu vàng ở dòng 2.
B6: 2. Làm xong bước nào thì tick ô ở cột "Xong" (hoặc gõ TRUE), ghi ngày xong và link Pull Request.
B7: 3. Dòng tô màu đậm là tên việc (mã, tuần, kết quả bàn giao, giờ); các dòng bên dưới là bước cần tick.
B8: 4. Dòng "✔ Kiểm tra" ở cuối mỗi việc: chỉ tick khi đã kiểm tra đúng như mô tả (test case, câu kiểm tra SQL...).
B9: 5. Sheet "Tổng quan" tự tính % tiến độ từng người và từng tuần. Sheet "Cổng kiểm tra" để cả nhóm tick ở buổi họp cuối giai đoạn.
B10: 6. Chỉ sửa: ô vàng (tên), cột Xong, Ngày xong, Link PR, Ghi chú. Không sửa các cột khác và công thức.
B12: Biến cột "Xong" thành ô tick (làm 1 lần)
B13: • Google Sheets: chọn cột "Xong" (từ dòng bảng đầu tiên xuống cuối) → menu Chèn (Insert) → Hộp kiểm (Checkbox). Các ô FALSE thành ô trống, TRUE thành ô đã tick.
B14: • Excel 365 (bản mới): chọn cột "Xong" → tab Insert → Checkbox. Bản Excel cũ không có nút này: gõ TRUE / FALSE vào ô, tiến độ vẫn tính đúng.
... B22: Dòng đã tick tự tô xanh nhạt và gạch ngang. TV1 xanh lá · TV2 cam · TV3 xanh dương · TV4 tím (theo kế hoạch).

Sheet Tổng quan
A1: Tổng quan tiến độ
A2: Tự tính từ cột "Xong" của các sheet TV1-TV4 và Cổng kiểm tra. Không sửa sheet này.
A4: Thành viên | B4: Tên | C4: Bước xong | D4: Tổng bước | E4: Tiến độ
A5: TV1 · Nền tảng, Tài khoản, Tiền | B5: ='TV1'!B2 | C5: =COUNTIF('TV1'!$H$6:$H$102,TRUE) | D5: =COUNTIF('TV1'!$H$6:$H$102,TRUE)+COUNTIF('TV1'!$H$6:$H$102,FALSE) | E5: =IFERROR(C5/D5,0)
A6: TV2 · Cửa hàng, Túi, Kho | B6: ='TV2'!B2 | C6: =COUNTIF('TV2'!$H$6:$H$77,TRUE) | D6: =COUNTIF('TV2'!$H$6:$H$77,TRUE)+COUNTIF('TV2'!$H$6:$H$77,FALSE) | E6: =IFERROR(C6/D6,0)
A7: TV3 · Khách hàng, Bản đồ, Giao diện chung | B7: ='TV3'!B2 | C7: =COUNTIF('TV3'!$H$6:$H$75,TRUE) | D7: =COUNTIF('TV3'!$H$6:$H$75,TRUE)+COUNTIF('TV3'!$H$6:$H$75,FALSE) | E7: =IFERROR(C7/D7,0)
A8: TV4 · Giỏ hàng, Đơn, Thanh toán, Giao hàng | B8: ='TV4'!B2 | C8: =COUNTIF('TV4'!$H$6:$H$68,TRUE) | D8: =COUNTIF('TV4'!$H$6:$H$68,TRUE)+COUNTIF('TV4'!$H$6:$H$68,FALSE) | E8: =IFERROR(C8/D8,0)
A9: Cả nhóm | C9: =SUM(C5:C8) | D9: =SUM(D5:D8) | E9: =IFERROR(C9/D9,0)
A11: Tiến độ theo tuần (bước xong / tổng bước của tuần đó)
A12: Tuần | B12: Giai đoạn | C12: TV1 | D12: TV2 | E12: TV3 | G12: TV4 | H12: Cả nhóm
A13: 1 | B13: GĐ0-1 | C13: =IF((COUNTIFS('TV1'!$L$6:$L$102,$A13,'TV1'!$H$6:$H$102,TRUE)+COUNTIFS('TV1'!$L$6:$L$102,$A13,'TV1'!$H$6:$H$102,FALSE))=0,"-",COUNTIFS('TV1'!$L$6:$L$102,$A13,'TV1'!$H$6:$H$102,TRUE)&"/"&(COUNTIFS('TV1'!$L$6:$L$102,$A13,'TV1'!$H$6:$H$102,TRUE)+COUNTIFS('TV1'!$L$6:$L$102,$A13,'TV1'!$H$6:$H$102,FALSE))) | D13: =IF((COUNTIFS('TV2'!$L$6:$L$77,$A13,'TV2'!$H$6:$H$77,TRUE)+COUNTIFS('TV2'!$L$6:$L$77,$A13,'TV2'!$H$6:$H$77,FALSE))=0,"-",COUNTIFS('TV2'!$L$6:$L$77,$A13,'TV2'!$H$6:$H$77,TRUE)&"/"&(COUNTIFS('TV2'!$L$6:$L$77,$A13,'TV2'!$H$6:$H$77,TRUE)+COUNTIFS('TV2'!$L$6:$L$77,$A13,'TV2'!$H$6:$H$77,FALSE))) | E13: =IF((COUNTIFS('TV3'!$L$6:$L$75,$A13,'TV3'!$H$6:$H$75,TRUE)+COUNTIFS('TV3'!$L$6:$L$75,$A13,'TV3'!$H$6:$H$75,FALSE))=0,"-",COUNTIFS('TV3'!$L$6:$L$75,$A13,'TV3'!$H$6:$H$75,TRUE)&"/"&(COUNTIFS('TV3'!$L$6:$L$75,$A13,'TV3'!$H$6:$H$75,TRUE)+COUNTIFS('TV3'!$L$6:$L$75,$A13,'TV3'!$H$6:$H$75,FALSE))) | G13: =IF((COUNTIFS('TV4'!$L$6:$L$68,$A13,'TV4'!$H$6:$H$68,TRUE)+COUNTIFS('TV4'!$L$6:$L$68,$A13,'TV4'!$H$6:$H$68,FALSE))=0,"-",COUNTIFS('TV4'!$L$6:$L$68,$A13,'TV4'!$H$6:$H$68,TRUE)&"/"&(COUNTIFS('TV4'!$L$6:$L$68,$A13,'TV4'!$H$6:$H$68,TRUE)+COUNTIFS('TV4'!$L$6:$L$68,$A13,'TV4'!$H$6:$H$68,FALSE))) | H13: =IFERROR((COUNTIFS('TV1'!$L$6:$L$102,$A13,'TV1'!$H$6:$H$102,TRUE)+COUNTIFS('TV2'!$L$6:$L$77,$A13,'TV2'!$H$6:$H$77,TRUE)+COUNTIFS('TV3'!$L$6:$L$75,$A13,'TV3'!$H$6:$H$75,TRUE)+COUNTIFS('TV4'!$L$6:$L$68,$A13,'TV4'!$H$6:$H$68,TRUE))/((COUNTIFS('TV1'!$L$6:$L$102,$A13,'TV1'!$H$6:$H$102,TRUE)+COUNTIFS('TV1'!$L$6:$L$102,$A13,'TV1'!$H$6:$H$102,FALSE))+(COUNTIFS('TV2'!$L$6:$L$77,$A13,'TV2'!$H$6:$H$77,TRUE)+COUNTIFS('TV2'!$L$6:$L$77,$A13,'TV2'!$H$6:$H$77,FALSE))+(COUNTIFS('TV3'!$L$6:$L$75,$A13,'TV3'!$H$6:$H$75,TRUE)+COUNTIFS('TV3'!$L$6:$L$75,$A13,'TV3'!$H$6:$H$75,FALSE))+(COUNTIFS('TV4'!$L$6:$L$68,$A13,'TV4'!$H$6:$H$68,TRUE)+COUNTIFS('TV4'!$L$6:$L$68,$A13,'TV4'!$H$6:$H$68,FALSE))),0)
A14: 2 | B14: GĐ2 | C14: =IF((COUNTIFS('TV1'!$L$6:$L$102,$A14,'TV1'!$H$6:$H$102,TRUE)+COUNTIFS('TV1'!$L$6:$L$102,$A14,'TV1'!$H$6:$H$102,FALSE))=0,"-",COUNTIFS('TV1'!$L$6:$L$102,$A14,'TV1'!$H$6:$H$102,TRUE)&"/"&(COUNTIFS('TV1'!$L$6:$L$102,$A14,'TV1'!$H$6:$H$102,TRUE)+COUNTIFS('TV1'!$L$6:$L$102,$A14,'TV1'!$H$6:$H$102,FALSE))) | D14: =IF((COUNTIFS('TV2'!$L$6:$L$77,$A14,'TV2'!$H$6:$H$77,TRUE)+COUNTIFS('TV2'!$L$6:$L$77,$A14,'TV2'!$H$6:$H$77,FALSE))=0,"-",COUNTIFS('TV2'!$L$6:$L$77,$A14,'TV2'!$H$6:$H$77,TRUE)&"/"&(COUNTIFS('TV2'!$L$6:$L$77,$A14,'TV2'!$H$6:$H$77,TRUE)+COUNTIFS('TV2'!$L$6:$L$77,$A14,'TV2'!$H$6:$H$77,FALSE))) | E14: =IF((COUNTIFS('TV3'!$L$6:$L$75,$A14,'TV3'!$H$6:$H$75,TRUE)+COUNTIFS('TV3'!$L$6:$L$75,$A14,'TV3'!$H$6:$H$75,FALSE))=0,"-",COUNTIFS('TV3'!$L$6:$L$75,$A14,'TV3'!$H$6:$H$75,TRUE)&"/"&(COUNTIFS('TV3'!$L$6:$L$75,$A14,'TV3'!$H$6:$H$75,TRUE)+COUNTIFS('TV3'!$L$6:$L$75,$A14,'TV3'!$H$6:$H$75,FALSE))) | G14: =IF((COUNTIFS('TV4'!$L$6:$L$68,$A14,'TV4'!$H$6:$H$68,TRUE)+COUNTIFS('TV4'!$L$6:$L$68,$A14,'TV4'!$H$6:$H$68,FALSE))=0,"-",COUNTIFS('TV4'!$L$6:$L$68,$A14,'TV4'!$H$6:$H$68,TRUE)&"/"&(COUNTIFS('TV4'!$L$6:$L$68,$A14,'TV4'!$H$6:$H$68,TRUE)+COUNTIFS('TV4'!$L$6:$L$68,$A14,'TV4'!$H$6:$H$68,FALSE))) | H14: =IFERROR((COUNTIFS('TV1'!$L$6:$L$102,$A14,'TV1'!$H$6:$H$102,TRUE)+COUNTIFS('TV2'!$L$6:$L$77,$A14,'TV2'!$H$6:$H$77,TRUE)+COUNTIFS('TV3'!$L$6:$L$75,$A14,'TV3'!$H$6:$H$75,TRUE)+COUNTIFS('TV4'!$L$6:$L$68,$A14,'TV4'!$H$6:$H$68,TRUE))/((COUNTIFS('TV1'!$L$6:$L$102,$A14,'TV1'!$H$6:$H$102,TRUE)+COUNTIFS('TV1'!$L$6:$L$102,$A14,'TV1'!$H$6:$H$102,FALSE))+(COUNTIFS('TV2'!$L$6:$L$77,$A14,'TV2'!$H$6:$H$77,TRUE)+COUNTIFS('TV2'!$L$6:$L$77,$A14,'TV2'!$H$6:$H$77,FALSE))+(COUNTIFS('TV3'!$L$6:$L$75,$A14,'TV3'!$H$6:$H$75,TRUE)+COUNTIFS('TV3'!$L$6:$L$75,$A14,'TV3'!$H$6:$H$75,FALSE))+(COUNTIFS('TV4'!$L$6:$L$68,$A14,'TV4'!$H$6:$H$68,TRUE)+COUNTIFS('TV4'!$L$6:$L$68,$A14,'TV4'!$H$6:$H$68,FALSE))),0)
A15: 3 | B15: GĐ2 | C15: =IF((COUNTIFS('TV1'!$L$6:$L$102,$A15,'TV1'!$H$6:$H$102,TRUE)+COUNTIFS('TV1'!$L$6:$L$102,$A15,'TV1'!$H$6:$H$102,FALSE))=0,"-",COUNTIFS('TV1'!$L$6:$L$102,$A15,'TV1'!$H$6:$H$102,TRUE)&"/"&(COUNTIFS('TV1'!$L$6:$L$102,$A15,'TV1'!$H$6:$H$102,TRUE)+COUNTIFS('TV1'!$L$6:$L$102,$A15,'TV1'!$H$6:$H$102,FALSE))) | D15: =IF((COUNTIFS('TV2'!$L$6:$L$77,$A15,'TV2'!$H$6:$H$77,TRUE)+COUNTIFS('TV2'!$L$6:$L$77,$A15,'TV2'!$H$6:$H$77,FALSE))=0,"-",COUNTIFS('TV2'!$L$6:$L$77,$A15,'TV2'!$H$6:$H$77,TRUE)&"/"&(COUNTIFS('TV2'!$L$6:$L$77,$A15,'TV2'!$H$6:$H$77,TRUE)+COUNTIFS('TV2'!$L$6:$L$77,$A15,'TV2'!$H$6:$H$77,FALSE))) | E15: =IF((COUNTIFS('TV3'!$L$6:$L$75,$A15,'TV3'!$H$6:$H$75,TRUE)+COUNTIFS('TV3'!$L$6:$L$75,$A15,'TV3'!$H$6:$H$75,FALSE))=0,"-",COUNTIFS('TV3'!$L$6:$L$75,$A15,'TV3'!$H$6:$H$75,TRUE)&"/"&(COUNTIFS('TV3'!$L$6:$L$75,$A15,'TV3'!$H$6:$H$75,TRUE)+COUNTIFS('TV3'!$L$6:$L$75,$A15,'TV3'!$H$6:$H$75,FALSE))) | G15: =IF((COUNTIFS('TV4'!$L$6:$L$68,$A15,'TV4'!$H$6:$H$68,TRUE)+COUNTIFS('TV4'!$L$6:$L$68,$A15,'TV4'!$H$6:$H$68,FALSE))=0,"-",COUNTIFS('TV4'!$L$6:$L$68,$A15,'TV4'!$H$6:$H$68,TRUE)&"/"&(COUNTIFS('TV4'!$L$6:$L$68,$A15,'TV4'!$H$6:$H$68,TRUE)+COUNTIFS('TV4'!$L$6:$L$68,$A15,'TV4'!$H$6:$H$68,FALSE))) | H15: =IFERROR((COUNTIFS('TV1'!$L$6:$L$102,$A15,'TV1'!$H$6:$H$102,TRUE)+COUNTIFS('TV2'!$L$6:$L$77,$A15,'TV2'!$H$6:$H$77,TRUE)+COUNTIFS('TV3'!$L$6:$L$75,$A15,'TV3'!$H$6:$H$75,TRUE)+COUNTIFS('TV4'!$L$6:$L$68,$A15,'TV4'!$H$6:$H$68,TRUE))/((COUNTIFS('TV1'!$L$6:$L$102,$A15,'TV1'!$H$6:$H$102,TRUE)+COUNTIFS('TV1'!$L$6:$L$102,$A15,'TV1'!$H$6:$H$102,FALSE))+(COUNTIFS('TV2'!$L$6:$L$77,$A15,'TV2'!$H$6:$H$77,TRUE)+COUNTIFS('TV2'!$L$6:$L$77,$A15,'TV2'!$H$6:$H$77,FALSE))+(COUNTIFS('TV3'!$L$6:$L$75,$A15,'TV3'!$H$6:$H$75,TRUE)+COUNTIFS('TV3'!$L$6:$L$75,$A15,'TV3'!$H$6:$H$75,FALSE))+(COUNTIFS('TV4'!$L$6:$L$68,$A15,'TV4'!$H$6:$H$68,TRUE)+COUNTIFS('TV4'!$L$6:$L$68,$A15,'TV4'!$H$6:$H$68,FALSE))),0)
A16: 4 | B16: GĐ3 | C16: =IF((COUNTIFS('TV1'!$L$6:$L$102,$A16,'TV1'!$H$6:$H$102,TRUE)+COUNTIFS('TV1'!$L$6:$L$102,$A16,'TV1'!$H$6:$H$102,FALSE))=0,"-",COUNTIFS('TV1'!$L$6:$L$102,$A16,'TV1'!$H$6:$H$102,TRUE)&"/"&(COUNTIFS('TV1'!$L$6:$L$102,$A16,'TV1'!$H$6:$H$102,TRUE)+COUNTIFS('TV1'!$L$6:$L$102,$A16,'TV1'!$H$6:$H$102,FALSE))) | D16: =IF((COUNTIFS('TV2'!$L$6:$L$77,$A16,'TV2'!$H$6:$H$77,TRUE)+COUNTIFS('TV2'!$L$6:$L$77,$A16,'TV2'!$H$6:$H$77,FALSE))=0,"-",COUNTIFS('TV2'!$L$6:$L$77,$A16,'TV2'!$H$6:$H$77,TRUE)&"/"&(COUNTIFS('TV2'!$L$6:$L$77,$A16,'TV2'!$H$6:$H$77,TRUE)+COUNTIFS('TV2'!$L$6:$L$77,$A16,'TV2'!$H$6:$H$77,FALSE))) | E16: =IF((COUNTIFS('TV3'!$L$6:$L$75,$A16,'TV3'!$H$6:$H$75,TRUE)+COUNTIFS('TV3'!$L$6:$L$75,$A16,'TV3'!$H$6:$H$75,FALSE))=0,"-",COUNTIFS('TV3'!$L$6:$L$75,$A16,'TV3'!$H$6:$H$75,TRUE)&"/"&(COUNTIFS('TV3'!$L$6:$L$75,$A16,'TV3'!$H$6:$H$75,TRUE)+COUNTIFS('TV3'!$L$6:$L$75,$A16,'TV3'!$H$6:$H$75,FALSE))) | G16: =IF((COUNTIFS('TV4'!$L$6:$L$68,$A16,'TV4'!$H$6:$H$68,TRUE)+COUNTIFS('TV4'!$L$6:$L$68,$A16,'TV4'!$H$6:$H$68,FALSE))=0,"-",COUNTIFS('TV4'!$L$6:$L$68,$A16,'TV4'!$H$6:$H$68,TRUE)&"/"&(COUNTIFS('TV4'!$L$6:$L$68,$A16,'TV4'!$H$6:$H$68,TRUE)+COUNTIFS('TV4'!$L$6:$L$68,$A16,'TV4'!$H$6:$H$68,FALSE))) | H16: =IFERROR((COUNTIFS('TV1'!$L$6:$L$102,$A16,'TV1'!$H$6:$H$102,TRUE)+COUNTIFS('TV2'!$L$6:$L$77,$A16,'TV2'!$H$6:$H$77,TRUE)+COUNTIFS('TV3'!$L$6:$L$75,$A16,'TV3'!$H$6:$H$75,TRUE)+COUNTIFS('TV4'!$L$6:$L$68,$A16,'TV4'!$H$6:$H$68,TRUE))/((COUNTIFS('TV1'!$L$6:$L$102,$A16,'TV1'!$H$6:$H$102,TRUE)+COUNTIFS('TV1'!$L$6:$L$102,$A16,'TV1'!$H$6:$H$102,FALSE))+(COUNTIFS('TV2'!$L$6:$L$77,$A16,'TV2'!$H$6:$H$77,TRUE)+COUNTIFS('TV2'!$L$6:$L$77,$A16,'TV2'!$H$6:$H$77,FALSE))+(COUNTIFS('TV3'!$L$6:$L$75,$A16,'TV3'!$H$6:$H$75,TRUE)+COUNTIFS('TV3'!$L$6:$L$75,$A16,'TV3'!$H$6:$H$75,FALSE))+(COUNTIFS('TV4'!$L$6:$L$68,$A16,'TV4'!$H$6:$H$68,TRUE)+COUNTIFS('TV4'!$L$6:$L$68,$A16,'TV4'!$H$6:$H$68,FALSE))),0)
A17: 5 | B17: GĐ3 | C17: =IF((COUNTIFS('TV1'!$L$6:$L$102,$A17,'TV1'!$H$6:$H$102,TRUE)+COUNTIFS('TV1'!$L$6:$L$102,$A17,'TV1'!$H$6:$H$102,FALSE))=0,"-",COUNTIFS('TV1'!$L$6:$L$102,$A17,'TV1'!$H$6:$H$102,TRUE)&"/"&(COUNTIFS('TV1'!$L$6:$L$102,$A17,'TV1'!$H$6:$H$102,TRUE)+COUNTIFS('TV1'!$L$6:$L$102,$A17,'TV1'!$H$6:$H$102,FALSE))) | D17: =IF((COUNTIFS('TV2'!$L$6:$L$77,$A17,'TV2'!$H$6:$H$77,TRUE)+COUNTIFS('TV2'!$L$6:$L$77,$A17,'TV2'!$H$6:$H$77,FALSE))=0,"-",COUNTIFS('TV2'!$L$6:$L$77,$A17,'TV2'!$H$6:$H$77,TRUE)&"/"&(COUNTIFS('TV2'!$L$6:$L$77,$A17,'TV2'!$H$6:$H$77,TRUE)+COUNTIFS('TV2'!$L$6:$L$77,$A17,'TV2'!$H$6:$H$77,FALSE))) | E17: =IF((COUNTIFS('TV3'!$L$6:$L$75,$A17,'TV3'!$H$6:$H$75,TRUE)+COUNTIFS('TV3'!$L$6:$L$75,$A17,'TV3'!$H$6:$H$75,FALSE))=0,"-",COUNTIFS('TV3'!$L$6:$L$75,$A17,'TV3'!$H$6:$H$75,TRUE)&"/"&(COUNTIFS('TV3'!$L$6:$L$75,$A17,'TV3'!$H$6:$H$75,TRUE)+COUNTIFS('TV3'!$L$6:$L$75,$A17,'TV3'!$H$6:$H$75,FALSE))) | G17: =IF((COUNTIFS('TV4'!$L$6:$L$68,$A17,'TV4'!$H$6:$H$68,TRUE)+COUNTIFS('TV4'!$L$6:$L$68,$A17,'TV4'!$H$6:$H$68,FALSE))=0,"-",COUNTIFS('TV4'!$L$6:$L$68,$A17,'TV4'!$H$6:$H$68,TRUE)&"/"&(COUNTIFS('TV4'!$L$6:$L$68,$A17,'TV4'!$H$6:$H$68,TRUE)+COUNTIFS('TV4'!$L$6:$L$68,$A17,'TV4'!$H$6:$H$68,FALSE))) | H17: =IFERROR((COUNTIFS('TV1'!$L$6:$L$102,$A17,'TV1'!$H$6:$H$102,TRUE)+COUNTIFS('TV2'!$L$6:$L$77,$A17,'TV2'!$H$6:$H$77,TRUE)+COUNTIFS('TV3'!$L$6:$L$75,$A17,'TV3'!$H$6:$H$75,TRUE)+COUNTIFS('TV4'!$L$6:$L$68,$A17,'TV4'!$H$6:$H$68,TRUE))/((COUNTIFS('TV1'!$L$6:$L$102,$A17,'TV1'!$H$6:$H$102,TRUE)+COUNTIFS('TV1'!$L$6:$L$102,$A17,'TV1'!$H$6:$H$102,FALSE))+(COUNTIFS('TV2'!$L$6:$L$77,$A17,'TV2'!$H$6:$H$77,TRUE)+COUNTIFS('TV2'!$L$6:$L$77,$A17,'TV2'!$H$6:$H$77,FALSE))+(COUNTIFS('TV3'!$L$6:$L$75,$A17,'TV3'!$H$6:$H$75,TRUE)+COUNTIFS('TV3'!$L$6:$L$75,$A17,'TV3'!$H$6:$H$75,FALSE))+(COUNTIFS('TV4'!$L$6:$L$68,$A17,'TV4'!$H$6:$H$68,TRUE)+COUNTIFS('TV4'!$L$6:$L$68,$A17,'TV4'!$H$6:$H$68,FALSE))),0)
A18: 6 | B18: GĐ4 | C18: =IF((COUNTIFS('TV1'!$L$6:$L$102,$A18,'TV1'!$H$6:$H$102,TRUE)+COUNTIFS('TV1'!$L$6:$L$102,$A18,'TV1'!$H$6:$H$102,FALSE))=0,"-",COUNTIFS('TV1'!$L$6:$L$102,$A18,'TV1'!$H$6:$H$102,TRUE)&"/"&(COUNTIFS('TV1'!$L$6:$L$102,$A18,'TV1'!$H$6:$H$102,TRUE)+COUNTIFS('TV1'!$L$6:$L$102,$A18,'TV1'!$H$6:$H$102,FALSE))) | D18: =IF((COUNTIFS('TV2'!$L$6:$L$77,$A18,'TV2'!$H$6:$H$77,TRUE)+COUNTIFS('TV2'!$L$6:$L$77,$A18,'TV2'!$H$6:$H$77,FALSE))=0,"-",COUNTIFS('TV2'!$L$6:$L$77,$A18,'TV2'!$H$6:$H$77,TRUE)&"/"&(COUNTIFS('TV2'!$L$6:$L$77,$A18,'TV2'!$H$6:$H$77,TRUE)+COUNTIFS('TV2'!$L$6:$L$77,$A18,'TV2'!$H$6:$H$77,FALSE))) | E18: =IF((COUNTIFS('TV3'!$L$6:$L$75,$A18,'TV3'!$H$6:$H$75,TRUE)+COUNTIFS('TV3'!$L$6:$L$75,$A18,'TV3'!$H$6:$H$75,FALSE))=0,"-",COUNTIFS('TV3'!$L$6:$L$75,$A18,'TV3'!$H$6:$H$75,TRUE)&"/"&(COUNTIFS('TV3'!$L$6:$L$75,$A18,'TV3'!$H$6:$H$75,TRUE)+COUNTIFS('TV3'!$L$6:$L$75,$A18,'TV3'!$H$6:$H$75,FALSE))) | G18: =IF((COUNTIFS('TV4'!$L$6:$L$68,$A18,'TV4'!$H$6:$H$68,TRUE)+COUNTIFS('TV4'!$L$6:$L$68,$A18,'TV4'!$H$6:$H$68,FALSE))=0,"-",COUNTIFS('TV4'!$L$6:$L$68,$A18,'TV4'!$H$6:$H$68,TRUE)&"/"&(COUNTIFS('TV4'!$L$6:$L$68,$A18,'TV4'!$H$6:$H$68,TRUE)+COUNTIFS('TV4'!$L$6:$L$68,$A18,'TV4'!$H$6:$H$68,FALSE))) | H18: =IFERROR((COUNTIFS('TV1'!$L$6:$L$102,$A18,'TV1'!$H$6:$H$102,TRUE)+COUNTIFS('TV2'!$L$6:$L$77,$A18,'TV2'!$H$6:$H$77,TRUE)+COUNTIFS('TV3'!$L$6:$L$75,$A18,'TV3'!$H$6:$H$75,TRUE)+COUNTIFS('TV4'!$L$6:$L$68,$A18,'TV4'!$H$6:$H$68,TRUE))/((COUNTIFS('TV1'!$L$6:$L$102,$A18,'TV1'!$H$6:$H$102,TRUE)+COUNTIFS('TV1'!$L$6:$L$102,$A18,'TV1'!$H$6:$H$102,FALSE))+(COUNTIFS('TV2'!$L$6:$L$77,$A18,'TV2'!$H$6:$H$77,TRUE)+COUNTIFS('TV2'!$L$6:$L$77,$A18,'TV2'!$H$6:$H$77,FALSE))+(COUNTIFS('TV3'!$L$6:$L$75,$A18,'TV3'!$H$6:$H$75,TRUE)+COUNTIFS('TV3'!$L$6:$L$75,$A18,'TV3'!$H$6:$H$75,FALSE))+(COUNTIFS('TV4'!$L$6:$L$68,$A18,'TV4'!$H$6:$H$68,TRUE)+COUNTIFS('TV4'!$L$6:$L$68,$A18,'TV4'!$H$6:$H$68,FALSE))),0)
A19: 7 | B19: GĐ4 | C19: =IF((COUNTIFS('TV1'!$L$6:$L$102,$A19,'TV1'!$H$6:$H$102,TRUE)+COUNTIFS('TV1'!$L$6:$L$102,$A19,'TV1'!$H$6:$H$102,FALSE))=0,"-",COUNTIFS('TV1'!$L$6:$L$102,$A19,'TV1'!$H$6:$H$102,TRUE)&"/"&(COUNTIFS('TV1'!$L$6:$L$102,$A19,'TV1'!$H$6:$H$102,TRUE)+COUNTIFS('TV1'!$L$6:$L$102,$A19,'TV1'!$H$6:$H$102,FALSE))) | D19: =IF((COUNTIFS('TV2'!$L$6:$L$77,$A19,'TV2'!$H$6:$H$77,TRUE)+COUNTIFS('TV2'!$L$6:$L$77,$A19,'TV2'!$H$6:$H$77,FALSE))=0,"-",COUNTIFS('TV2'!$L$6:$L$77,$A19,'TV2'!$H$6:$H$77,TRUE)&"/"&(COUNTIFS('TV2'!$L$6:$L$77,$A19,'TV2'!$H$6:$H$77,TRUE)+COUNTIFS('TV2'!$L$6:$L$77,$A19,'TV2'!$H$6:$H$77,FALSE))) | E19: =IF((COUNTIFS('TV3'!$L$6:$L$75,$A19,'TV3'!$H$6:$H$75,TRUE)+COUNTIFS('TV3'!$L$6:$L$75,$A19,'TV3'!$H$6:$H$75,FALSE))=0,"-",COUNTIFS('TV3'!$L$6:$L$75,$A19,'TV3'!$H$6:$H$75,TRUE)&"/"&(COUNTIFS('TV3'!$L$6:$L$75,$A19,'TV3'!$H$6:$H$75,TRUE)+COUNTIFS('TV3'!$L$6:$L$75,$A19,'TV3'!$H$6:$H$75,FALSE))) | G19: =IF((COUNTIFS('TV4'!$L$6:$L$68,$A19,'TV4'!$H$6:$H$68,TRUE)+COUNTIFS('TV4'!$L$6:$L$68,$A19,'TV4'!$H$6:$H$68,FALSE))=0,"-",COUNTIFS('TV4'!$L$6:$L$68,$A19,'TV4'!$H$6:$H$68,TRUE)&"/"&(COUNTIFS('TV4'!$L$6:$L$68,$A19,'TV4'!$H$6:$H$68,TRUE)+COUNTIFS('TV4'!$L$6:$L$68,$A19,'TV4'!$H$6:$H$68,FALSE))) | H19: =IFERROR((COUNTIFS('TV1'!$L$6:$L$102,$A19,'TV1'!$H$6:$H$102,TRUE)+COUNTIFS('TV2'!$L$6:$L$77,$A19,'TV2'!$H$6:$H$77,TRUE)+COUNTIFS('TV3'!$L$6:$L$75,$A19,'TV3'!$H$6:$H$75,TRUE)+COUNTIFS('TV4'!$L$6:$L$68,$A19,'TV4'!$H$6:$H$68,TRUE))/((COUNTIFS('TV1'!$L$6:$L$102,$A19,'TV1'!$H$6:$H$102,TRUE)+COUNTIFS('TV1'!$L$6:$L$102,$A19,'TV1'!$H$6:$H$102,FALSE))+(COUNTIFS('TV2'!$L$6:$L$77,$A19,'TV2'!$H$6:$H$77,TRUE)+COUNTIFS('TV2'!$L$6:$L$77,$A19,'TV2'!$H$6:$H$77,FALSE))+(COUNTIFS('TV3'!$L$6:$L$75,$A19,'TV3'!$H$6:$H$75,TRUE)+COUNTIFS('TV3'!$L$6:$L$75,$A19,'TV3'!$H$6:$H$75,FALSE))+(COUNTIFS('TV4'!$L$6:$L$68,$A19,'TV4'!$H$6:$H$68,TRUE)+COUNTIFS('TV4'!$L$6:$L$68,$A19,'TV4'!$H$6:$H$68,FALSE))),0)
A20: 8 | B20: GĐ5 | C20: =IF((COUNTIFS('TV1'!$L$6:$L$102,$A20,'TV1'!$H$6:$H$102,TRUE)+COUNTIFS('TV1'!$L$6:$L$102,$A20,'TV1'!$H$6:$H$102,FALSE))=0,"-",COUNTIFS('TV1'!$L$6:$L$102,$A20,'TV1'!$H$6:$H$102,TRUE)&"/"&(COUNTIFS('TV1'!$L$6:$L$102,$A20,'TV1'!$H$6:$H$102,TRUE)+COUNTIFS('TV1'!$L$6:$L$102,$A20,'TV1'!$H$6:$H$102,FALSE))) | D20: =IF((COUNTIFS('TV2'!$L$6:$L$77,$A20,'TV2'!$H$6:$H$77,TRUE)+COUNTIFS('TV2'!$L$6:$L$77,$A20,'TV2'!$H$6:$H$77,FALSE))=0,"-",COUNTIFS('TV2'!$L$6:$L$77,$A20,'TV2'!$H$6:$H$77,TRUE)&"/"&(COUNTIFS('TV2'!$L$6:$L$77,$A20,'TV2'!$H$6:$H$77,TRUE)+COUNTIFS('TV2'!$L$6:$L$77,$A20,'TV2'!$H$6:$H$77,FALSE))) | E20: =IF((COUNTIFS('TV3'!$L$6:$L$75,$A20,'TV3'!$H$6:$H$75,TRUE)+COUNTIFS('TV3'!$L$6:$L$75,$A20,'TV3'!$H$6:$H$75,FALSE))=0,"-",COUNTIFS('TV3'!$L$6:$L$75,$A20,'TV3'!$H$6:$H$75,TRUE)&"/"&(COUNTIFS('TV3'!$L$6:$L$75,$A20,'TV3'!$H$6:$H$75,TRUE)+COUNTIFS('TV3'!$L$6:$L$75,$A20,'TV3'!$H$6:$H$75,FALSE))) | G20: =IF((COUNTIFS('TV4'!$L$6:$L$68,$A20,'TV4'!$H$6:$H$68,TRUE)+COUNTIFS('TV4'!$L$6:$L$68,$A20,'TV4'!$H$6:$H$68,FALSE))=0,"-",COUNTIFS('TV4'!$L$6:$L$68,$A20,'TV4'!$H$6:$H$68,TRUE)&"/"&(COUNTIFS('TV4'!$L$6:$L$68,$A20,'TV4'!$H$6:$H$68,TRUE)+COUNTIFS('TV4'!$L$6:$L$68,$A20,'TV4'!$H$6:$H$68,FALSE))) | H20: =IFERROR((COUNTIFS('TV1'!$L$6:$L$102,$A20,'TV1'!$H$6:$H$102,TRUE)+COUNTIFS('TV2'!$L$6:$L$77,$A20,'TV2'!$H$6:$H$77,TRUE)+COUNTIFS('TV3'!$L$6:$L$75,$A20,'TV3'!$H$6:$H$75,TRUE)+COUNTIFS('TV4'!$L$6:$L$68,$A20,'TV4'!$H$6:$H$68,TRUE))/((COUNTIFS('TV1'!$L$6:$L$102,$A20,'TV1'!$H$6:$H$102,TRUE)+COUNTIFS('TV1'!$L$6:$L$102,$A20,'TV1'!$H$6:$H$102,FALSE))+(COUNTIFS('TV2'!$L$6:$L$77,$A20,'TV2'!$H$6:$H$77,TRUE)+COUNTIFS('TV2'!$L$6:$L$77,$A20,'TV2'!$H$6:$H$77,FALSE))+(COUNTIFS('TV3'!$L$6:$L$75,$A20,'TV3'!$H$6:$H$75,TRUE)+COUNTIFS('TV3'!$L$6:$L$75,$A20,'TV3'!$H$6:$H$75,FALSE))+(COUNTIFS('TV4'!$L$6:$L$68,$A20,'TV4'!$H$6:$H$68,TRUE)+COUNTIFS('TV4'!$L$6:$L$68,$A20,'TV4'!$H$6:$H$68,FALSE))),0)
A22: Cổng kiểm tra
A23: Cổng | B23: Điều kiện đạt | C23: Trạng thái
A24: G0 · Cuối tuần 1, ngày 2 | B24: =COUNTIFS('Cổng kiểm tra'!$A$5:$A$33,"G0",'Cổng kiểm tra'!$D$5:$D$33,TRUE)&"/"&COUNTIF('Cổng kiểm tra'!$A$5:$A$33,"G0") | C24: =IF(COUNTIFS('Cổng kiểm tra'!$A$5:$A$33,"G0",'Cổng kiểm tra'!$D$5:$D$33,TRUE)=COUNTIF('Cổng kiểm tra'!$A$5:$A$33,"G0"),"ĐẠT","Chưa")
A25: G1 · Cuối tuần 1 (họp ~90 phút) | B25: =COUNTIFS('Cổng kiểm tra'!$A$5:$A$33,"G1",'Cổng kiểm tra'!$D$5:$D$33,TRUE)&"/"&COUNTIF('Cổng kiểm tra'!$A$5:$A$33,"G1") | C25: =IF(COUNTIFS('Cổng kiểm tra'!$A$5:$A$33,"G1",'Cổng kiểm tra'!$D$5:$D$33,TRUE)=COUNTIF('Cổng kiểm tra'!$A$5:$A$33,"G1"),"ĐẠT","Chưa")
A26: G2 · Cuối tuần 3 | B26: =COUNTIFS('Cổng kiểm tra'!$A$5:$A$33,"G2",'Cổng kiểm tra'!$D$5:$D$33,TRUE)&"/"&COUNTIF('Cổng kiểm tra'!$A$5:$A$33,"G2") | C26: =IF(COUNTIFS('Cổng kiểm tra'!$A$5:$A$33,"G2",'Cổng kiểm tra'!$D$5:$D$33,TRUE)=COUNTIF('Cổng kiểm tra'!$A$5:$A$33,"G2"),"ĐẠT","Chưa")
A27: G3 · Cuối tuần 5 | B27: =COUNTIFS('Cổng kiểm tra'!$A$5:$A$33,"G3",'Cổng kiểm tra'!$D$5:$D$33,TRUE)&"/"&COUNTIF('Cổng kiểm tra'!$A$5:$A$33,"G3") | C27: =IF(COUNTIFS('Cổng kiểm tra'!$A$5:$A$33,"G3",'Cổng kiểm tra'!$D$5:$D$33,TRUE)=COUNTIF('Cổng kiểm tra'!$A$5:$A$33,"G3"),"ĐẠT","Chưa")
A28: G4 · Cuối tuần 7 | B28: =COUNTIFS('Cổng kiểm tra'!$A$5:$A$33,"G4",'Cổng kiểm tra'!$D$5:$D$33,TRUE)&"/"&COUNTIF('Cổng kiểm tra'!$A$5:$A$33,"G4") | C28: =IF(COUNTIFS('Cổng kiểm tra'!$A$5:$A$33,"G4",'Cổng kiểm tra'!$D$5:$D$33,TRUE)=COUNTIF('Cổng kiểm tra'!$A$5:$A$33,"G4"),"ĐẠT","Chưa")
A29: GĐ5 · Tuần 8 | B29: =COUNTIFS('Cổng kiểm tra'!$A$5:$A$33,"GĐ5",'Cổng kiểm tra'!$D$5:$D$33,TRUE)&"/"&COUNTIF('Cổng kiểm tra'!$A$5:$A$33,"GĐ5") | C29: =IF(COUNTIFS('Cổng kiểm tra'!$A$5:$A$33,"GĐ5",'Cổng kiểm tra'!$D$5:$D$33,TRUE)=COUNTIF('Cổng kiểm tra'!$A$5:$A$33,"GĐ5"),"ĐẠT","Chưa")

Sheet TV1
A1: Checklist TV1 · Nền tảng, Tài khoản, Tiền
A2: Thành viên: | F2: Tiến độ: | G2: =IFERROR(COUNTIF($H$6:$H$102,TRUE)/(COUNTIF($H$6:$H$102,TRUE)+COUNTIF($H$6:$H$102,FALSE)),0) | H2: =COUNTIF($H$6:$H$102,TRUE)&"/"&(COUNTIF($H$6:$H$102,TRUE)+COUNTIF($H$6:$H$102,FALSE))&" bước"
A3: Tick cột "Xong" khi làm xong từng bước. Ô vàng là ô được sửa. Xem sheet "Hướng dẫn".
A5: Mã | B5: Tuần | C5: Việc | D5: Bước cần làm | E5: Cần có trước | F5: Kết quả bàn giao / cách kiểm tra | G5: Giờ | H5: Xong | I5: Ngày xong | J5: Link PR | K5: Ghi chú | L5: Tuần số
A6: C0 | B6: 1 · N1-2 | C6: Chuẩn bị máy (cả nhóm) | E6: — | F6: Máy chạy được CSDL, backend, frontend | G6: 2 | L6: 1
A7: C0 | B7: 1 · N1-2 | D7: Cài JDK 17+, Maven, Node.js 22, Git, XAMPP, VS Code + extension (Java, Spring Boot, Prettier, EditorConfig) | H7: FALSE | L7: 1
A8: C0 | B8: 1 · N1-2 | D8: Clone repo vào thư mục KHÔNG dấu, git checkout develop | H8: FALSE | L8: 1
A9: C0 | B9: 1 · N1-2 | D9: Tạo CSDL bằng database/foodrescue_schema.sql (XAMPP), chạy foodrescue_checks.sql thấy sạch | H9: FALSE | L9: 1
A10: C0 | B10: 1 · N1-2 | D10: Tạo application-local.yml từ file .example; mvn spring-boot:run; mở /api/ping thấy ok | H10: FALSE | L10: 1
A11: C0 | B11: 1 · N1-2 | D11: npm install, npm run dev; mở localhost:5173 thấy "đã nối được backend" | H11: FALSE | L11: 1
A12: C0 | B12: 1 · N1-2 | D12: Đọc tài liệu dự án mục 2-5 và toàn bộ Quy ước chung | H12: FALSE | L12: 1
A13: C0 | B13: 1 · N1-2 | D13: Tạo nhánh đầu tiên, mở 1 Pull Request thử, thấy CI chạy | H13: FALSE | L13: 1
A14: C0 | B14: 1 · N1-2 | D14: ✔ Kiểm tra: C0 chênh lệch 0; C1-C12 không trả dòng nào | H14: FALSE | L14: 1
A15: F1 | B15: 1 · N1 | C15: Tạo repo | E15: — | F15: Repo có develop; mọi người clone được | G15: 2 | L15: 1
A16: F1 | B16: 1 · N1 | D16: Tạo repo foodrescue gồm backend/, frontend/, database/, docs/. | H16: FALSE | L16: 1
A17: F1 | B17: 1 · N1 | D17: Chép .editorconfig, .gitattributes, .github/ từ quy_uoc_chung; chép 2 file SQL vào database/. | H17: FALSE | L17: 1
A18: F1 | B18: 1 · N1 | D18: Tạo nhánh develop; bảo vệ main, develop (bắt buộc PR + 1 duyệt). | H18: FALSE | L18: 1
A19: F1 | B19: 1 · N1 | D19: Tạo nhãn shared-change, api, db, bug; bảng GitHub Projects 5 cột. | H19: FALSE | L19: 1
A20: F1 | B20: 1 · N1 | D20: Mời 3 thành viên. | H20: FALSE | L20: 1
A21: F1 | B21: 1 · N1 | D21: ✔ Kiểm tra: Push thẳng lên develop bị từ chối | H21: FALSE | L21: 1
A22: F2 | B22: 1 · N1-2 | C22: Khung Spring Boot | E22: F1 | F22: mvn spring-boot:run nối được foodrescuedb; Swagger mở được | G22: 5 | L22: 1
A23: F2 | B23: 1 · N1-2 | D23: Spring Initializr: Java 17, Boot 3.3.x, Web, Data JPA, Security, Validation, MySQL Driver, Lombok; thêm jjwt, springdoc-openapi. | H23: FALSE | L23: 1
A24: F2 | B24: 1 · N1-2 | D24: Chép quy_uoc_chung/backend (common/*, application.yml, MoneyTest). | H24: FALSE | L24: 1
A25: F2 | B25: 1 · N1-2 | D25: Tạo application-local.example.yml (mật khẩu MySQL, JWT, VNPay), thêm bản thật vào .gitignore. | H25: FALSE | L25: 1
A26: F2 | B26: 1 · N1-2 | D26: CORS cho localhost:5173. | H26: FALSE | L26: 1
A27: F2 | B27: 1 · N1-2 | D27: API GET /api/ping công khai. | H27: FALSE | L27: 1
A28: F2 | B28: 1 · N1-2 | D28: ✔ Kiểm tra: MoneyTest pass; /api/ping trả 200 | H28: FALSE | L28: 1
A29: F5 | B29: 1 · N1-2 | C29: Khung React | E29: F1 | F29: npm run dev thấy 3 khu; npm run build chạy được | G29: 8 | L29: 1
A30: F5 | B30: 1 · N1-2 | D30: Vite + React; cài antd @ant-design/icons axios react-router-dom dayjs react-leaflet leaflet qrcode.react recharts. | H30: FALSE | L30: 1
A31: F5 | B31: 1 · N1-2 | D31: Chép quy_uoc_chung/frontend; thêm font Be Vietnam Pro; bọc ConfigProvider theme={antdTheme} locale={viVN}. | H31: FALSE | L31: 1
A32: F5 | B32: 1 · N1-2 | D32: 3 layout: Customer (header trắng), Store và Admin (menu trái). | H32: FALSE | L32: 1
A33: F5 | B33: 1 · N1-2 | D33: app/routes.jsx gộp routes của 5 feature; tạo sẵn file routes.jsx, menu.js rỗng cho cả 4 người. | H33: FALSE | L33: 1
A34: F5 | B34: 1 · N1-2 | D34: PrivateRoute roles=[...], lưu đăng nhập trong localStorage. | H34: FALSE | L34: 1
A35: F5 | B35: 1 · N1-2 | D35: Vite proxy /api sang 8080. | H35: FALSE | L35: 1
A36: F5 | B36: 1 · N1-2 | D36: ✔ Kiểm tra: Mở /admin khi chưa đăng nhập thì về /login | H36: FALSE | L36: 1
A37: F3 | B37: 1 · N3 | C37: 13 entity | E37: F2 | F37: 13 entity + 13 repository; sau đó chỉ sửa qua PR [DB] | G37: 6 | L37: 1
A38: F3 | B38: 1 · N3 | D38: Viết entity cho 13 bảng theo "Ghi chú JPA" (tài liệu dự án mục 10): @IdClass cho cart_items, enum dạng STRING, tiền BigDecimal, @ManyToOne(fetch = LAZY), @Immutable cho StockMovement, AuditLog. | H38: FALSE | L38: 1
A39: F3 | B39: 1 · N3 | D39: Repository cơ bản cho từng entity. | H39: FALSE | L39: 1
A40: F3 | B40: 1 · N3 | D40: Chạy ứng dụng với ddl-auto=validate, sửa đến khi hết lỗi. | H40: FALSE | L40: 1
A41: F3 | B41: 1 · N3 | D41: ✔ Kiểm tra: Ứng dụng khởi động không lỗi validate | H41: FALSE | L41: 1
...

Sheet TV2
A1: Checklist TV2 · Cửa hàng, Túi, Kho
A2: Thành viên: | F2: Tiến độ: | G2: =IFERROR(COUNTIF($H$6:$H$77,TRUE)/(COUNTIF($H$6:$H$77,TRUE)+COUNTIF($H$6:$H$77,FALSE)),0) | H2: =COUNTIF($H$6:$H$77,TRUE)&"/"&(COUNTIF($H$6:$H$77,TRUE)+COUNTIF($H$6:$H$77,FALSE))&" bước"
A3: Tick cột "Xong" khi làm xong từng bước. Ô vàng là ô được sửa. Xem sheet "Hướng dẫn".
A5: Mã | B5: Tuần | C5: Việc | D5: Bước cần làm | E5: Cần có trước | F5: Kết quả bàn giao / cách kiểm tra | G5: Giờ | H5: Xong | I5: Ngày xong | J5: Link PR | K5: Ghi chú | L5: Tuần số
A6: C0 | B6: 1 · N1-2 | C6: Chuẩn bị máy (cả nhóm) | E6: — | F6: Máy chạy được CSDL, backend, frontend | G6: 2 | L6: 1
A7: C0 | B7: 1 · N1-2 | D7: Cài JDK 17+, Maven, Node.js 22, Git, XAMPP, VS Code + extension (Java, Spring Boot, Prettier, EditorConfig) | H7: FALSE | L7: 1
A8: C0 | B8: 1 · N1-2 | D8: Clone repo vào thư mục KHÔNG dấu, git checkout develop | H8: FALSE | L8: 1
A9: C0 | B9: 1 · N1-2 | D9: Tạo CSDL bằng database/foodrescue_schema.sql (XAMPP), chạy foodrescue_checks.sql thấy sạch | H9: FALSE | L9: 1
A10: C0 | B10: 1 · N1-2 | D10: Tạo application-local.yml từ file .example; mvn spring-boot:run; mở /api/ping thấy ok | H10: FALSE | L10: 1
A11: C0 | B11: 1 · N1-2 | D11: npm install, npm run dev; mở localhost:5173 thấy "đã nối được backend" | H11: FALSE | L11: 1
A12: C0 | B12: 1 · N1-2 | D12: Đọc tài liệu dự án mục 2-5 và toàn bộ Quy ước chung | H12: FALSE | L12: 1
A13: C0 | B13: 1 · N1-2 | D13: Tạo nhánh đầu tiên, mở 1 Pull Request thử, thấy CI chạy | H13: FALSE | L13: 1
A14: C0 | B14: 1 · N1-2 | D14: ✔ Kiểm tra: C0 chênh lệch 0; C1-C12 không trả dòng nào | H14: FALSE | L14: 1
A15: S0 | B15: 1 · N1-3 | C15: Ghim bản đồ, giao diện tĩnh | E15: — | F15: Component ghim + 2 trang tĩnh | G15: 5 | L15: 1
A16: S0 | B16: 1 · N1-3 | D16: LocationPicker (react-leaflet): bấm hoặc kéo ghim → trả {lat, lng}, chặn toạ độ ngoài Việt Nam. | H16: FALSE | L16: 1
A17: S0 | B17: 1 · N1-3 | D17: Giao diện tĩnh trang đăng ký cửa hàng (3 bước) và trang quản lý túi, dùng component của TV3. | H17: FALSE | L17: 1
A18: S0 | B18: 1 · N1-3 | D18: ✔ Kiểm tra: Ghim ra đúng toạ độ | H18: FALSE | L18: 1
A19: H2 | B19: 1 · N4-5 | C19: Hợp đồng API | E19: F4 | F19: API hiện trên Swagger | G19: 3 | L19: 1
A20: H2 | B20: 1 · N4-5 | D20: DTO + controller dữ liệu giả cho /api/auth/register-store, /api/admin/stores*, /api/admin/users*, /api/store/batches*, quantity, stock-movements, profile, staff, revenue, statement, payouts. | H20: FALSE | L20: 1
A21: H2 | B21: 1 · N4-5 | D21: ✔ Kiểm tra: Duyệt ở G1 | H21: FALSE | L21: 1
A22: S1 | B22: 2 | C22: API đăng ký cửa hàng | E22: F4, F6 | F22: Đăng ký bằng Postman ra cửa hàng PENDING | G22: 5 | L22: 2
A23: S1 | B23: 2 | D23: POST /api/auth/register-store (multipart): tạo user STORE_OWNER + store PENDING trong 1 transaction; lưu ảnh giấy phép qua FileStorageService. | H23: FALSE | L23: 2
A24: S1 | B24: 2 | D24: Kiểm tra: email trùng, giờ đóng > giờ mở, toạ độ trong Việt Nam, đủ tài khoản ngân hàng. | H24: FALSE | L24: 2
A25: S1 | B25: 2 | D25: Chủ quán chưa duyệt đăng nhập thì storeStatus = PENDING. | H25: FALSE | L25: 2
A26: S1 | B26: 2 | D26: ✔ Kiểm tra: Đăng ký lần 2 cùng email → EMAIL_EXISTS | H26: FALSE | L26: 2
A27: S2 | B27: 2 | C27: Trang đăng ký cửa hàng | E27: S1 | F27: Đăng ký được trên giao diện | G27: 6 | L27: 2
A28: S2 | B28: 2 | D28: /store/register: Steps tài khoản → cửa hàng + ghim → giấy phép + ngân hàng. | H28: FALSE | L28: 2
A29: S2 | B29: 2 | D29: Xong thì báo "Chờ admin duyệt". | H29: FALSE | L29: 2
A30: S2 | B30: 2 | D30: Chủ quán PENDING đăng nhập thấy trang "Đang chờ duyệt". | H30: FALSE | L30: 2
A31: S2 | B31: 2 | D31: ✔ Kiểm tra: Thử với dữ liệu thiếu, sai | H31: FALSE | L31: 2
A32: S3 | B32: 3 | C32: Admin duyệt cửa hàng | E32: F8, seed | F32: Duyệt GreenMart với phí 10% | G32: 8 | L32: 3
A33: S3 | B33: 3 | D33: GET /api/admin/stores?status; approve (kèm tỉ lệ phí, mặc định 15%), reject (bắt buộc lý do), lock, unlock; PUT .../commission. | H33: FALSE | L33: 3
A34: S3 | B34: 3 | D34: Ghi log từng thao tác. | H34: FALSE | L34: 3
A35: S3 | B35: 3 | D35: Trang /admin/stores: tab theo trạng thái, xem ảnh giấy phép, bản đồ vị trí. | H35: FALSE | L35: 3
A36: S3 | B36: 3 | D36: ✔ Kiểm tra: Nhật ký có STORE_APPROVED | H36: FALSE | L36: 3
A37: S4 | B37: 3 | C37: API túi | E37: F8 | F37: Tạo, sửa túi bằng API | G37: 7 | L37: 3
A38: S4 | B38: 3 | D38: GET/POST/PUT /api/store/batches (multipart có ảnh), chỉ túi của cửa hàng mình. | H38: FALSE | L38: 3
A39: S4 | B39: 3 | D39: Kiểm tra giá ≤ 60% (Money.isValidRescuePrice), khung giờ, cửa hàng đã duyệt; túi đã có đơn thì không sửa giá / khung giờ. | H39: FALSE | L39: 3
A40: S4 | B40: 3 | D40: Tạo túi gọi StockService.adjust(LISTED). | H40: FALSE | L40: 3
A41: S4 | B41: 3 | D41: ✔ Kiểm tra: TC09; C1b sạch | H41: FALSE | L41: 3
...

Sheet TV3
A1: Checklist TV3 · Khách hàng, Bản đồ, Giao diện chung
A2: Thành viên: | F2: Tiến độ: | G2: =IFERROR(COUNTIF($H$6:$H$75,TRUE)/(COUNTIF($H$6:$H$75,TRUE)+COUNTIF($H$6:$H$75,FALSE)),0) | H2: =COUNTIF($H$6:$H$75,TRUE)&"/"&(COUNTIF($H$6:$H$75,TRUE)+COUNTIF($H$6:$H$75,FALSE))&" bước"
A3: Tick cột "Xong" khi làm xong từng bước. Ô vàng là ô được sửa. Xem sheet "Hướng dẫn".
A5: Mã | B5: Tuần | C5: Việc | D5: Bước cần làm | E5: Cần có trước | F5: Kết quả bàn giao / cách kiểm tra | G5: Giờ | H5: Xong | I5: Ngày xong | J5: Link PR | K5: Ghi chú | L5: Tuần số
A6: C0 | B6: 1 · N1-2 | C6: Chuẩn bị máy (cả nhóm) | E6: — | F6: Máy chạy được CSDL, backend, frontend | G6: 2 | L6: 1
A7: C0 | B7: 1 · N1-2 | D7: Cài JDK 17+, Maven, Node.js 22, Git, XAMPP, VS Code + extension (Java, Spring Boot, Prettier, EditorConfig) | H7: FALSE | L7: 1
A8: C0 | B8: 1 · N1-2 | D8: Clone repo vào thư mục KHÔNG dấu, git checkout develop | H8: FALSE | L8: 1
A9: C0 | B9: 1 · N1-2 | D9: Tạo CSDL bằng database/foodrescue_schema.sql (XAMPP), chạy foodrescue_checks.sql thấy sạch | H9: FALSE | L9: 1
A10: C0 | B10: 1 · N1-2 | D10: Tạo application-local.yml từ file .example; mvn spring-boot:run; mở /api/ping thấy ok | H10: FALSE | L10: 1
A11: C0 | B11: 1 · N1-2 | D11: npm install, npm run dev; mở localhost:5173 thấy "đã nối được backend" | H11: FALSE | L11: 1
A12: C0 | B12: 1 · N1-2 | D12: Đọc tài liệu dự án mục 2-5 và toàn bộ Quy ước chung | H12: FALSE | L12: 1
A13: C0 | B13: 1 · N1-2 | D13: Tạo nhánh đầu tiên, mở 1 Pull Request thử, thấy CI chạy | H13: FALSE | L13: 1
A14: C0 | B14: 1 · N1-2 | D14: ✔ Kiểm tra: C0 chênh lệch 0; C1-C12 không trả dòng nào | H14: FALSE | L14: 1
A15: B0 | B15: 1 · N1-2 | C15: Thử OSRM, làm ảnh | E15: — | F15: Kết quả OSRM; bộ ảnh trong frontend/src/assets | G15: 5 | L15: 1
A16: B0 | B16: 1 · N1-2 | D16: Class Java nháp gọi OSRM Table API, in mét / giây (nhớ thứ tự kinh độ, vĩ độ). | H16: FALSE | L16: 1
A17: B0 | B17: 1 · N1-2 | D17: 6 ảnh danh mục PNG nền trong (đặt tên theo image_url trong SQL) + 3 banner (Canva) theo Quy ước chung mục 6.4. | H17: FALSE | L17: 1
A18: B0 | B18: 1 · N1-2 | D18: ✔ Kiểm tra: So quãng đường với Google Maps | H18: FALSE | L18: 1
A19: B14 | B19: 1 · N3-5 | C19: Bộ component dùng chung | E19: F5 | F19: Bộ component cho cả nhóm; trang chủ tĩnh giống mô phỏng | G19: 6 | L19: 1
A20: B14 | B20: 1 · N3-5 | D20: Trong shared/components: SiteHeader (logo, "Vị trí nhận hàng", ô tìm kiếm, Đăng nhập / Đăng ký, chỗ icon giỏ), CategoryStrip, BatchCard, PriceTag, MoneyText, StatusTag, DistanceText, PickupWindow, PageHeader, StatCard, EmptyState, ConfirmAction. | H20: FALSE | L20: 1
A21: B14 | B21: 1 · N3-5 | D21: Chỉ dùng theme.js, status.js, format.js. | H21: FALSE | L21: 1
A22: B14 | B22: 1 · N3-5 | D22: Trang chủ tĩnh với dữ liệu giả. | H22: FALSE | L22: 1
A23: B14 | B23: 1 · N3-5 | D23: ✔ Kiểm tra: TV1 duyệt PR (nhãn shared-change) | H23: FALSE | L23: 1
A24: H3 | B24: 1 · N4-5 | C24: Hợp đồng API | E24: F4 | F24: API hiện trên Swagger | G24: 3 | L24: 1
A25: H3 | B25: 1 · N4-5 | D25: DTO + controller dữ liệu giả cho /api/categories, /api/batches, /api/batches/{id}, /api/stores/{id} (+ reviews), /api/orders/{id}/review, /api/admin/categories, /api/admin/dashboard. | H25: FALSE | L25: 1
A26: H3 | B26: 1 · N4-5 | D26: ✔ Kiểm tra: Duyệt ở G1 | H26: FALSE | L26: 1
A27: B1 | B27: 2 | C27: API danh sách túi | E27: F3 | F27: API trả túi thật | G27: 6 | L27: 2
A28: B1 | B28: 2 | D28: GET /api/categories theo sort_order. | H28: FALSE | L28: 2
A29: B1 | B29: 2 | D29: GET /api/batches: chỉ túi AVAILABLE, chưa hết giờ, của cửa hàng APPROVED; lọc danh mục, từ khoá; sắp xếp rẻ nhất / sắp hết giờ; PageResponse. | H29: FALSE | L29: 2
A30: B1 | B30: 2 | D30: ✔ Kiểm tra: Túi của cửa hàng PENDING không hiện | H30: FALSE | L30: 2
A31: B2 | B31: 2 | C31: Trang chủ | E31: B1, B14 | F31: Trang chủ chạy dữ liệu thật | G31: 6 | L31: 2
A32: B2 | B32: 2 | D32: Nối CategoryStrip, lưới BatchCard với API. | H32: FALSE | L32: 2
A33: B2 | B33: 2 | D33: Tab "Danh sách / Bản đồ", chọn bán kính, sắp xếp, "Xem thêm". | H33: FALSE | L33: 2
A34: B2 | B34: 2 | D34: Trạng thái đang tải (Skeleton), trạng thái rỗng. | H34: FALSE | L34: 2
A35: B2 | B35: 2 | D35: ✔ Kiểm tra: Lọc danh mục đúng | H35: FALSE | L35: 2
A36: B3 | B36: 3 | C36: Tính khoảng cách | E36: B1 | F36: Mọi thẻ túi có khoảng cách | G36: 9 | L36: 3
A37: B3 | B37: 3 | D37: Lọc cửa hàng bằng ST_Distance_Sphere trong bán kính (≤ 30). | H37: FALSE | L37: 3
A38: B3 | B38: 3 | D38: Gọi OSRM 1 lần, timeout 2 giây. | H38: FALSE | L38: 3
A39: B3 | B39: 3 | D39: Lỗi thì dùng chim bay × 1,3 và estimated = true. | H39: FALSE | L39: 3
A40: B3 | B40: 3 | D40: Sắp xếp "gần nhất". | H40: FALSE | L40: 3
A41: B3 | B41: 3 | D41: Unit test trường hợp OSRM lỗi. | H41: FALSE | L41: 3
...

Sheet TV4
A1: Checklist TV4 · Giỏ hàng, Đơn, Thanh toán, Giao hàng
A2: Thành viên: | F2: Tiến độ: | G2: =IFERROR(COUNTIF($H$6:$H$68,TRUE)/(COUNTIF($H$6:$H$68,TRUE)+COUNTIF($H$6:$H$68,FALSE)),0) | H2: =COUNTIF($H$6:$H$68,TRUE)&"/"&(COUNTIF($H$6:$H$68,TRUE)+COUNTIF($H$6:$H$68,FALSE))&" bước"
A3: Tick cột "Xong" khi làm xong từng bước. Ô vàng là ô được sửa. Xem sheet "Hướng dẫn".
A5: Mã | B5: Tuần | C5: Việc | D5: Bước cần làm | E5: Cần có trước | F5: Kết quả bàn giao / cách kiểm tra | G5: Giờ | H5: Xong | I5: Ngày xong | J5: Link PR | K5: Ghi chú | L5: Tuần số
A6: C0 | B6: 1 · N1-2 | C6: Chuẩn bị máy (cả nhóm) | E6: — | F6: Máy chạy được CSDL, backend, frontend | G6: 2 | L6: 1
A7: C0 | B7: 1 · N1-2 | D7: Cài JDK 17+, Maven, Node.js 22, Git, XAMPP, VS Code + extension (Java, Spring Boot, Prettier, EditorConfig) | H7: FALSE | L7: 1
A8: C0 | B8: 1 · N1-2 | D8: Clone repo vào thư mục KHÔNG dấu, git checkout develop | H8: FALSE | L8: 1
A9: C0 | B9: 1 · N1-2 | D9: Tạo CSDL bằng database/foodrescue_schema.sql (XAMPP), chạy foodrescue_checks.sql thấy sạch | H9: FALSE | L9: 1
A10: C0 | B10: 1 · N1-2 | D10: Tạo application-local.yml từ file .example; mvn spring-boot:run; mở /api/ping thấy ok | H10: FALSE | L10: 1
A11: C0 | B11: 1 · N1-2 | D11: npm install, npm run dev; mở localhost:5173 thấy "đã nối được backend" | H11: FALSE | L11: 1
A12: C0 | B12: 1 · N1-2 | D12: Đọc tài liệu dự án mục 2-5 và toàn bộ Quy ước chung | H12: FALSE | L12: 1
A13: C0 | B13: 1 · N1-2 | D13: Tạo nhánh đầu tiên, mở 1 Pull Request thử, thấy CI chạy | H13: FALSE | L13: 1
A14: C0 | B14: 1 · N1-2 | D14: ✔ Kiểm tra: C0 chênh lệch 0; C1-C12 không trả dòng nào | H14: FALSE | L14: 1
A15: O0 | B15: 1 · N1-3 | C15: Chuẩn bị VNPay | E15: — | F15: Hàm ký đúng; đã trả tiền thử thành công | G15: 6 | L15: 1
A16: O0 | B16: 1 · N1-3 | D16: Đăng ký merchant sandbox, nhận vnp_TmnCode, vnp_HashSecret, gửi nhóm qua tin nhắn riêng. | H16: FALSE | L16: 1
A17: O0 | B17: 1 · N1-3 | D17: VnPaySigner: sắp xếp tham số, URL-encode, HMAC-SHA512 + unit test. | H17: FALSE | L17: 1
A18: O0 | B18: 1 · N1-3 | D18: Tạo 1 link thật, trả bằng thẻ NCB test. | H18: FALSE | L18: 1
A19: O0 | B19: 1 · N1-3 | D19: ✔ Kiểm tra: Link mở được trang VNPay | H19: FALSE | L19: 1
A20: H4 | B20: 1 · N4-5 | C20: Hợp đồng API | E20: F4 | F20: API hiện trên Swagger | G20: 3 | L20: 1
A21: H4 | B21: 1 · N4-5 | D21: DTO + controller dữ liệu giả cho /api/cart*, /api/orders*, /api/payments/vnpay/*, /api/store/orders*, /api/store/pickup/*. | H21: FALSE | L21: 1
A22: H4 | B22: 1 · N4-5 | D22: ✔ Kiểm tra: Duyệt ở G1 | H22: FALSE | L22: 1
A23: O12 | B23: 2 | C23: API giỏ hàng | E23: F3 | F23: Giỏ hàng chạy qua Postman | G23: 4 | L23: 2
A24: O12 | B24: 2 | D24: GET /api/cart (giá, số còn lại mới nhất, đánh dấu túi hết / hết giờ, khung giờ chung, canCheckout); thêm (1-5 mỗi loại), sửa, xoá, xoá hết; túi khác cửa hàng → CART_OTHER_STORE. | H24: FALSE | L24: 2
A25: O12 | B25: 2 | D25: ✔ Kiểm tra: TC21 (backend) | H25: FALSE | L25: 2
A26: O1 | B26: 2 | C26: API tạo đơn | E26: F8, O12 | F26: Tạo đơn nhiều túi đúng tiền, đúng kho | G26: 9 | L26: 2
A27: O1 | B27: 2 | D27: POST /api/orders lấy giỏ của khách. | H27: FALSE | L27: 2
A28: O1 | B28: 2 | D28: Kiểm tra túi còn bán, cùng cửa hàng, có khung giờ chung. | H28: FALSE | L28: 2
A29: O1 | B29: 2 | D29: Trong 1 transaction: StockService.reserve từng túi theo id tăng dần (thiếu thì rollback, báo túi nào); tạo orders + order_items; mã đơn, mã nhận hàng; phí theo stores.commission_rate qua Money; payments PENDING; xoá giỏ. | H29: FALSE | L29: 2
A30: O1 | B30: 2 | D30: ✔ Kiểm tra: C1-C5 sạch sau khi tạo đơn | H30: FALSE | L30: 2
A31: O2 | B31: 2 | C31: Test đặt đồng thời | E31: O1 | F31: Test tự động chạy trong CI | G31: 4 | L31: 2
A32: O2 | B32: 2 | D32: Test JUnit: 10 luồng cùng đặt túi còn 1; đơn 2 loại túi mà 1 loại thiếu. | H32: FALSE | L32: 2
A33: O2 | B33: 2 | D33: ✔ Kiểm tra: TC01, TC22 | H33: FALSE | L33: 2
A34: O3 | B34: 3 | C34: Tích hợp VNPay | E34: O0, O1 | F34: Thanh toán thật trên sandbox | G34: 9 | L34: 3
A35: O3 | B35: 3 | D35: Tạo paymentUrl (hết hạn 10 phút). | H35: FALSE | L35: 3
A36: O3 | B36: 3 | D36: /api/payments/vnpay/return và /ipn cùng gọi confirm(): kiểm tra chữ ký, số tiền; chỉ xử lý 1 lần; 00 → CONFIRMED + PAID + log; mã khác → EXPIRED + trả kho. | H36: FALSE | L36: 3
A37: O3 | B37: 3 | D37: Tiền về khi đơn đã EXPIRED: còn hàng thì giữ lại và CONFIRMED, hết thì RefundService(LATE_PAYMENT). | H37: FALSE | L37: 3
A38: O3 | B38: 3 | D38: ✔ Kiểm tra: TC02, TC03, TC04, TC17 | H38: FALSE | L38: 3
A39: O4 | B39: 3 | C39: Giỏ hàng, kết quả thanh toán | E39: O12, O3 | F39: Mua hàng trọn vẹn trên giao diện | G39: 8 | L39: 3
A40: O4 | B40: 3 | D40: <AddToCartButton> giao TV3; hook useCart cho icon giỏ trên header. | H40: FALSE | L40: 3
A41: O4 | B41: 3 | D41: Trang /cart: danh sách túi, sửa số lượng, tổng tiền, khung giờ chung, cảnh báo túi hết, nút "Đặt hàng". | H41: FALSE | L41: 3
...

Sheet Cổng kiểm tra
A1: Cổng kiểm tra cuối mỗi giai đoạn
A2: Tick ở buổi họp cuối giai đoạn. Chưa đủ thì chưa sang giai đoạn sau (Kế hoạch mục 3).
A4: Cổng | B4: Thời điểm | C4: Điều kiện | D4: Đạt | E4: Ngày | F4: Người xác nhận | G4: Ghi chú
A5: G0 | B5: Cuối tuần 1, ngày 2 | C5: git clone → mvn spring-boot:run chạy; /swagger-ui.html mở được | D5: FALSE
A6: G0 | C6: Gọi /api/orders không token trả 401 dạng ApiError | D6: FALSE
A7: G0 | C7: npm run dev thấy 3 khu (khách, cửa hàng, admin), mỗi khu trang "Đang xây dựng" | D7: FALSE
A8: G0 | C8: MoneyTest pass; CI xanh trên develop | D8: FALSE
A9: G0 | C9: Mỗi người đã tạo nhánh đầu tiên và mở PR thử | D9: FALSE
A10: G1 | B10: Cuối tuần 1 (họp ~90 phút) | C10: Swagger trên develop hiện đủ API ở mục 8 tài liệu dự án (trả dữ liệu giả đúng định dạng) | D10: FALSE
A11: G1 | C11: Cả nhóm duyệt tên trường JSON theo từ điển thuật ngữ | D11: FALSE
A12: G1 | C12: Entity khớp CSDL (ứng dụng chạy với ddl-auto=validate) | D12: FALSE
A13: G1 | C13: StockService có test giữ hàng; TC25 (trigger) đạt | D13: FALSE
A14: G1 | C14: Trang chủ tĩnh đạt mẫu mục 6.4 Quy ước chung | D14: FALSE
A15: G1 | C15: TV1 gắn tag v0.1 | D15: FALSE
A16: G2 | B16: Cuối tuần 3 | C16: Đăng ký GreenMart → admin duyệt với phí 10% | D16: FALSE
A17: G2 | C17: Chủ quán tạo được túi | D17: FALSE
A18: G2 | C18: Khách thấy túi trên trang chủ kèm khoảng cách, lọc được danh mục | D18: FALSE
A19: G2 | C19: Thêm 2 loại túi vào giỏ → đặt → trả thẻ test VNPay → đơn CONFIRMED + PAID | D19: FALSE
A20: G2 | C20: Đạt TC01, TC02, TC03, TC04, TC06, TC09, TC21, TC22 | D20: FALSE
A21: G2 | C21: foodrescue_checks.sql sạch; tag v0.3 | D21: FALSE
A22: G3 | B22: Cuối tuần 5 | C22: Chạy được bước 1-6 kịch bản demo mục 14.2 tài liệu dự án | D22: FALSE
A23: G3 | C23: Đạt TC05, TC07, TC08, TC17, TC18, TC23, TC26 | D23: FALSE
A24: G3 | C24: Nạp demo_data.sql xong foodrescue_checks.sql vẫn sạch | D24: FALSE
A25: G3 | C25: Tag v0.5 lên main | D25: FALSE
A26: G4 | B26: Cuối tuần 7 | C26: Đạt TC10-TC16, TC19, TC24 | D26: FALSE
A27: G4 | C27: Chạy đủ 26 test case một lượt, ghi kết quả | D27: FALSE
A28: G4 | C28: Trang đối soát và câu C0 cùng ra chênh lệch 0 | D28: FALSE
A29: G4 | C29: Dừng thêm tính năng mới; tag v0.9 | D29: FALSE
A30: GĐ5 | B30: Tuần 8 | C30: Ngày 1: chạy lại schema; test chéo (TV1→TV4, TV2→TV3, TV3→TV2, TV4→TV1); ghi lỗi vào Issues | D30: FALSE
A31: GĐ5 | C31: Ngày 2-3: sửa lỗi mức cao (tiền, kho, phân quyền); chạy lại checks và 26 test case | D31: FALSE
A32: GĐ5 | C32: Ngày 4: merge develop → main, tag v1.0, (tuỳ chọn) deploy; mỗi người viết phần báo cáo | D32: FALSE
A33: GĐ5 | C33: Ngày 5: ghép báo cáo, slide; tập demo 2 lần; quay video dự phòng | D33: FALSE
